Traceback (most recent call last):
  File "C:\Users\chjch\AppData\Local\ESRI\conda\envs\arcpro-py3-clone\lib\site-packages\jupyter_cache\executors\utils.py", line 51, in single_nb_execution
    executenb(
  File "C:\Users\chjch\AppData\Local\ESRI\conda\envs\arcpro-py3-clone\lib\site-packages\nbclient\client.py", line 1204, in execute
    return NotebookClient(nb=nb, resources=resources, km=km, **kwargs).execute()
  File "C:\Users\chjch\AppData\Local\ESRI\conda\envs\arcpro-py3-clone\lib\site-packages\nbclient\util.py", line 84, in wrapped
    return just_run(coro(*args, **kwargs))
  File "C:\Users\chjch\AppData\Local\ESRI\conda\envs\arcpro-py3-clone\lib\site-packages\nbclient\util.py", line 62, in just_run
    return loop.run_until_complete(coro)
  File "C:\Users\chjch\AppData\Local\ESRI\conda\envs\arcpro-py3-clone\lib\asyncio\base_events.py", line 647, in run_until_complete
    return future.result()
  File "C:\Users\chjch\AppData\Local\ESRI\conda\envs\arcpro-py3-clone\lib\site-packages\nbclient\client.py", line 663, in async_execute
    await self.async_execute_cell(
  File "C:\Users\chjch\AppData\Local\ESRI\conda\envs\arcpro-py3-clone\lib\site-packages\nbclient\client.py", line 965, in async_execute_cell
    await self._check_raise_for_error(cell, cell_index, exec_reply)
  File "C:\Users\chjch\AppData\Local\ESRI\conda\envs\arcpro-py3-clone\lib\site-packages\nbclient\client.py", line 862, in _check_raise_for_error
    raise CellExecutionError.from_cell_and_msg(cell, exec_reply_content)
nbclient.exceptions.CellExecutionError: An error occurred while executing the following cell:
------------------
arcpy.env.extent = "county_boundary" # set extent by a feature class
------------------

[1;31m---------------------------------------------------------------------------[0m
[1;31mRuntimeError[0m                              Traceback (most recent call last)
[1;32m<ipython-input-4-120bc8ea6529>[0m in [0;36m<module>[1;34m[0m
[1;32m----> 1[1;33m [0marcpy[0m[1;33m.[0m[0menv[0m[1;33m.[0m[0mextent[0m [1;33m=[0m [1;34m"county_boundary"[0m [1;31m# set extent by a feature class[0m[1;33m[0m[1;33m[0m[0m
[0m
[1;32mC:\Program Files\ArcGIS\Pro\Resources\ArcPy\arcpy\geoprocessing\_base.py[0m in [0;36mset_[1;34m(self, val)[0m
[0;32m    541[0m             [1;32mif[0m [0mhasattr[0m[1;33m([0m[0mval[0m[1;33m,[0m [1;34m'_arc_object'[0m[1;33m)[0m[1;33m:[0m[1;33m[0m[1;33m[0m[0m
[0;32m    542[0m                 [0mval[0m [1;33m=[0m [0mval[0m[1;33m.[0m[0m_arc_object[0m[1;33m[0m[1;33m[0m[0m
[1;32m--> 543[1;33m             [0mself[0m[1;33m[[0m[0menv[0m[1;33m][0m [1;33m=[0m [0mval[0m[1;33m[0m[1;33m[0m[0m
[0m[0;32m    544[0m         [1;32mdef[0m [0mdel_[0m[1;33m([0m[0mself[0m[1;33m)[0m[1;33m:[0m[1;33m[0m[1;33m[0m[0m
[0;32m    545[0m             [1;32mdel[0m [0mself[0m[1;33m[[0m[0menv[0m[1;33m][0m[1;33m[0m[1;33m[0m[0m

[1;32mC:\Program Files\ArcGIS\Pro\Resources\ArcPy\arcpy\geoprocessing\_base.py[0m in [0;36m__setitem__[1;34m(self, item, value)[0m
[0;32m    605[0m             [1;32mif[0m [0mhasattr[0m[1;33m([0m[0mvalue[0m[1;33m,[0m [1;34m'_arc_object'[0m[1;33m)[0m[1;33m:[0m[1;33m[0m[1;33m[0m[0m
[0;32m    606[0m                 [0mvalue[0m [1;33m=[0m [0mvalue[0m[1;33m.[0m[0m_arc_object[0m[1;33m[0m[1;33m[0m[0m
[1;32m--> 607[1;33m             [0mret_[0m [1;33m=[0m [0msetattr[0m[1;33m([0m[0mself[0m[1;33m.[0m[0m_gp[0m[1;33m,[0m [0mitem[0m[1;33m,[0m [0mvalue[0m[1;33m)[0m[1;33m[0m[1;33m[0m[0m
[0m[0;32m    608[0m             [1;32mif[0m [0mneed_refresh[0m[1;33m:[0m[1;33m[0m[1;33m[0m[0m
[0;32m    609[0m                 [0mself[0m[1;33m.[0m[0m_refresh[0m[1;33m([0m[1;33m)[0m[1;33m[0m[1;33m[0m[0m

[1;31mRuntimeError[0m: Object: Error in accessing environment <extent>
RuntimeError: Object: Error in accessing environment <extent>

